Workbook

Sheet 🏠 Паспорт на имота
A1: 🏠 ПАСПОРТ НА ИМОТА — Пълни данни и характеристики
A2: Real Mentor | Управление на недвижим имот
A4: А. ОСНОВНИ ДАННИ ЗА ИМОТА
B5: Адрес на имота | E5: Град / Квартал / Улица / Блок / Ап.
B6: Тип имот | E6: Апартамент / Къща / Студио / Гараж
B7: Жилищна площ (кв.м) | E7: По нотариален акт
B8: Застроена площ (кв.м) | E8: Вкл. дебелина на стените
B9: Етаж | E9: Напр. 4 от 10
B10: Изложение | E10: Юг / Север / Изток / Запад / Комб.
B11: Вид конструкция | E11: Панел / Тухла / ЕПК / Нова сграда
B12: Година на строеж
B13: Кадастрален идентификатор | E13: По КРНИ — задължителен
B14: Нотариален акт № | E14: Том / Рег. / Дело
B15: Нотариус | E15: Имe и нотариален район
B16: Имотен регистър | E16: Служба по вписванията
A18: Б. ПРИДОБИВАНЕ — Финансови данни
B19: Дата на придобиване | E19: Дата на нотариален акт
B20: Покупна цена (лв.) | E20: По нотариален акт
B21: Покупна цена (EUR) | E21: По фиксинга БНБ 1.95583
B22: Нотариални такси и данъци (лв.) | E22: Местен данък + нотариус + вписване
B23: Брокерска комисионна (лв.) | E23: Ако е платена
B24: Ремонт при придобиване (лв.) | E24: Вж. лист Ремонти
B25: Обзавеждане при придобиване (лв.) | E25: Вж. лист Обзавеждане
B26: ОБЩА ИНВЕСТИЦИЯ (лв.) | C26: =C18+C19+C20+C21+C22+C23 -> 0 | E26: Автоматично
B27: ОБЩА ИНВЕСТИЦИЯ (EUR) | C27: =C24/1.95583 -> 0 | E27: По фиксинга БНБ
A30: В. ТЕХНИЧЕСКИ ХАРАКТЕРИСТИКИ
B31: Отопление | C31: Климатик | E31: ЦО / Климатик / Печка / ТЛ / Газ
B32: Топла вода | C32: Бойлер + топлофикация | E32: Бойлер / ЦО / Слънчев колектор
B33: Климатизация | C33: Bosh | E33: Марка, модел, брой тела
B34: Дограма | E34: PVC / Алуминий / Дърво | Двойно/Тройно стъкло
B35: Подови настилки | E35: Паркет / Ламинат / Теракот / LVP
B36: Интернет оператор | E36: Доставчик + скорост
B37: ТВ / Кабелен | E37: Оператор
B38: Гараж / Паркинг | E38: Номер / Закрит / Открит
B39: Мазе | E39: Номер / кв.м
B40: Стан/Перилня | E40: Достъп до перилня в сградата
B41: Вход / Код | E41: Входен код на сграда
B42: Домофон | E42: Номер и системa
A45: Г. ПАРТИДИ, АБОНАТНИ НОМЕРА И ДОСТАВЧИЦИ — Всички услуги
B46: Услуга | C46: Абон. / Партиден № | D46: Доставчик | E46: Клиентски № | F46: Обслужващ офис / Телефон | G46: Бележки
...

Sheet 👤 Наематели
A1: 👤 НАЕМАТЕЛИ — Текущи и минали договори
A2: Попълнете данните за всеки наемател — жълтите клетки
A4: А. ТЕКУЩ НАЕМАТЕЛ
B5: Три имена на наемателя
B6: ЕГН / Лична карта №
B7: Телефон
B8: Имейл
B9: Постоянен адрес
B10: Работодател / Фирма | D10: Или студент / пенсионер
B11: Контакт при спешност | D11: Имe + Телефон
B12: Начало на договора | D12: дата
B13: Край на договора | D13: дата
B14: Месечен наем (EUR) | C14: 600
B15: Месечен наем (лв.) | C15: =IF(C14="","",C14*1.95583) -> 1173.498 | D15: по фиксинга БНБ
B16: Ден на плащане | C16: 5 | D16: до кое число на месеца
B17: IBAN на наемодателя
B18: Депозит платен — сума (EUR) | C18: 1200
B19: Депозит платен — дата | D19: дата
B20: Депозит върнат — сума | C20: 600
B21: Депозит върнат — дата | C21: 46112 | D21: дата
B22: Брой живеещи лица | C22: 2
B23: Домашни любимци | C23: Не | D23: Да / Не / Вид
B24: Нотариална заверка | C24: Не | D24: Да / Не
B25: Застраховка на наемателя | C25: Не | D25: Да / Не
B26: Бележки
A28: Б. ИСТОРИЯ НА НАЕМАТЕЛИТЕ — Хронология
A29: № | B29: Наемател | C29: Начало | D29: Край | E29: Мес. наем (EUR) | F29: Депозит (EUR) | G29: Причина напускане | H29: Бележки
A30: 1
A31: 2
A32: 3
A33: 4
A34: 5
A35: 6
A36: 7
A37: 8
A38: 9
A39: 10

Sheet 💶 Плащания наем
A1: 💶 ПЛАЩАНИЯ НА НАЕМ — Хронологичен регистър
A2: Отбелязвайте всяко плащане — автоматично се изчисляват просрочия
A4: Общо начислено (EUR) | C4: Общо получено (EUR) | E4: Разлика (δ EUR) | G4: Брой записа | I4: Закъснения (записа)
A5: =IFERROR(SUM(D8:D500),0) -> 600 | C5: =IFERROR(SUM(F8:F500),0) -> 600 | E5: =IFERROR(C5-E5,0) -> 0 | G5: =IFERROR(COUNTA(B8:B500),0) -> 1 | I5: =IFERROR(COUNTIF(H8:H500,">0"),0) -> 1
A7: № | B7: Период (мес.) | C7: Дата падеж | D7: Начислено (EUR) | E7: Получено? | F7: Получена сума (EUR) | G7: Дата плащане | H7: Закъснение (дни) | I7: Забележка / Начин | J7: Бележки
A8: 1 | B8: 1 | C8: 46117 | D8: 600 | E8: Да | F8: 600 | G8: 46122 | H8: =IFERROR(IF(G8="","",MAX(0,G8-C8)),"") -> 5
A9: 2 | C9: 46147 | H9: =IFERROR(IF(G9="","",MAX(0,G9-C9)),"")
A10: 3 | C10: 46178 | H10: =IFERROR(IF(G10="","",MAX(0,G10-C10)),"")
A11: 4 | H11: =IFERROR(IF(G11="","",MAX(0,G11-C11)),"")
A12: 5 | H12: =IFERROR(IF(G12="","",MAX(0,G12-C12)),"")
A13: 6 | H13: =IFERROR(IF(G13="","",MAX(0,G13-C13)),"")
A14: 7 | H14: =IFERROR(IF(G14="","",MAX(0,G14-C14)),"")
A15: 8 | H15: =IFERROR(IF(G15="","",MAX(0,G15-C15)),"")
A16: 9 | H16: =IFERROR(IF(G16="","",MAX(0,G16-C16)),"")
A17: 10 | H17: =IFERROR(IF(G17="","",MAX(0,G17-C17)),"")
A18: 11 | H18: =IFERROR(IF(G18="","",MAX(0,G18-C18)),"")
A19: 12 | H19: =IFERROR(IF(G19="","",MAX(0,G19-C19)),"")
A20: 13 | H20: =IFERROR(IF(G20="","",MAX(0,G20-C20)),"")
A21: 14 | H21: =IFERROR(IF(G21="","",MAX(0,G21-C21)),"")
A22: 15 | H22: =IFERROR(IF(G22="","",MAX(0,G22-C22)),"")
... A43: 36 | H43: =IFERROR(IF(G43="","",MAX(0,G43-C43)),"")

Sheet 📋 Разходи и сметки
A1: 📋 РАЗХОДИ И СМЕТКИ — Всички плащания свързани с имота
A2: Фиксирани + Променливи + Данъци + ЕСС + Застраховки
A4: Общо разходи (EUR) | C4: Фиксирани | E4: Променливи | G4: Данъци/Такси | I4: Ремонти
A6: № | B6: Дата | C6: Описание / Категория | D6: Сума (EUR) | E6: Сума (лв.) | F6: Фактура № | G6: Плащане | H6: Категория | I6: Бележки
A7: 1 | E7: =IFERROR(D7*1.95583,"") -> 0
A8: 2 | E8: =IFERROR(D8*1.95583,"") -> 0
A9: 3 | E9: =IFERROR(D9*1.95583,"") -> 0
A10: 4 | E10: =IFERROR(D10*1.95583,"") -> 0
A11: 5 | E11: =IFERROR(D11*1.95583,"") -> 0
A12: 6 | E12: =IFERROR(D12*1.95583,"") -> 0
A13: 7 | E13: =IFERROR(D13*1.95583,"") -> 0
A14: 8 | E14: =IFERROR(D14*1.95583,"") -> 0
A15: 9 | E15: =IFERROR(D15*1.95583,"") -> 0
A16: 10 | E16: =IFERROR(D16*1.95583,"") -> 0
A17: 11 | E17: =IFERROR(D17*1.95583,"") -> 0
A18: 12 | E18: =IFERROR(D18*1.95583,"") -> 0
... A66: 60 | E66: =IFERROR(D66*1.95583,"") -> 0

Sheet 🔨 Ремонти
A1: 🔨 РЕМОНТИ, ПОПРАВКИ И ПОДОБРЕНИЯ — Пълна история
A2: Всяко вложение в имота — материали, труд и обща стойност
A3: 💰 Общо вложено (EUR) | D3: 🔧 Брой ремонти | G3: 📅 Последен ремонт
A4: =IFERROR(SUM(F7:F200),0) -> 0 | D4: =COUNTA(C7:C200) -> 0 | G4: =IFERROR(MAX(B7:B200),"") -> 0
A6: № | B6: Дата | C6: Описание / Вид ремонт | D6: Изпълнител | E6: Материали (EUR) | F6: Труд (EUR) | G6: Общо (EUR) | H6: Гаранция до | I6: Приоритет | J6: Бележки / Фактури
A7: 1 | G7: =IFERROR(E7+F7,0) -> 0
A8: 2 | G8: =IFERROR(E8+F8,0) -> 0
A9: 3 | G9: =IFERROR(E9+F9,0) -> 0
A10: 4 | G10: =IFERROR(E10+F10,0) -> 0
A11: 5 | G11: =IFERROR(E11+F11,0) -> 0
A12: 6 | G12: =IFERROR(E12+F12,0) -> 0
A13: 7 | G13: =IFERROR(E13+F13,0) -> 0
A14: 8 | G14: =IFERROR(E14+F14,0) -> 0
A15: 9 | G15: =IFERROR(E15+F15,0) -> 0
A16: 10 | G16: =IFERROR(E16+F16,0) -> 0
A17: 11 | G17: =IFERROR(E17+F17,0) -> 0
A18: 12 | G18: =IFERROR(E18+F18,0) -> 0
... A56: 50 | G56: =IFERROR(E56+F56,0) -> 0

Sheet 🛋️ Обзавеждане
A1: 🛋️ ОБЗАВЕЖДАНЕ И ИНВЕНТАР — Пълен опис
A2: Всяка мебел, уред и предмет в имота — с дата, цена и гаранция
A3: № | B3: Дата закупено | C3: Артикул / Описание | D3: Местонахождение | E3: Кол. | F3: Ед. цена (EUR) | G3: Обща цена (EUR) | H3: Сост. | I3: Гаранция до | J3: Бележки / Марка
A4: 1 | C4: Диван / Ъглов диван | D4: Хол | E4: 1 | G4: =IFERROR(E4*F4,0) -> 0
A5: 2 | C5: Холна маса | D5: Хол | E5: 1 | G5: =IFERROR(E5*F5,0) -> 0
A6: 3 | C6: ТВ | D6: Хол | E6: 1 | G6: =IFERROR(E6*F6,0) -> 0
A7: 4 | C7: Шкаф / Скрин | D7: Хол | E7: 1 | G7: =IFERROR(E7*F7,0) -> 0
A8: 5 | C8: Климатик | D8: Хол | E8: 1 | G8: =IFERROR(E8*F8,0) -> 0
A9: 6 | C9: Легло + матрак | D9: Спалня | E9: 1 | G9: =IFERROR(E9*F9,0) -> 0
A10: 7 | C10: Гардероб | D10: Спалня | E10: 1 | G10: =IFERROR(E10*F10,0) -> 0
A11: 8 | C11: Нощни шкафчета | D11: Спалня | E11: 2 | G11: =IFERROR(E11*F11,0) -> 0
A12: 9 | C12: Хладилник | D12: Кухня | E12: 1 | G12: =IFERROR(E12*F12,0) -> 0
A13: 10 | C13: Готварска печка / Котлон | D13: Кухня | E13: 1 | G13: =IFERROR(E13*F13,0) -> 0
A14: 11 | C14: Фурна | D14: Кухня | E14: 1 | G14: =IFERROR(E14*F14,0) -> 0
A15: 12 | C15: Абсорбатор | D15: Кухня | E15: 1 | G15: =IFERROR(E15*F15,0) -> 0
... A23: 20 | C23: Прахосмукачка | D23: Общо | E23: 1 | G23: =IFERROR(E23*F23,0) -> 0
A24: 🏷️ ОБЩА СТОЙНОСТ НА ОБЗАВЕЖДАНЕТО | G24: =IFERROR(SUM(G4:G23),0) -> 0

Sheet 📊 Финансово резюме
A1: 📊 ФИНАНСОВО РЕЗЮМЕ — Обобщен преглед на инвестицията
A2: Автоматично изчислено от данните в другите листове
A4: А. ИНВЕСТИЦИЯ | F4: Д. ВАЖНИ КОНТАКТИ И БЕЛЕЖКИ
B5: Покупна цена (EUR) | C5: ='🏠 Паспорт на имота'!C19 -> 0 | F5: 👨‍🔧 ВиК майстор:
B6: Ремонт и обзавеждане (EUR) | C6: =IFERROR('🔨 Ремонти'!G4+'🛋️ Обзавеждане'!G24,0) -> 0 | F6: ⚡ Електротехник:
B7: Нотариус и такси (EUR) | C7: =IFERROR('🏠 Паспорт на имота'!C20/1.95583,0) -> 0 | F7: 🏢 Управител ЕСС:
B8: ОБЩА ИНВЕСТИЦИЯ (EUR) | C8: ='🏠 Паспорт на имота'!C25 -> 0 | F8: ⚖️ Адвокат:
B9: Дата на придобиване | C9: ='🏠 Паспорт на имота'!C17 -> 0 | F9: 📋 Счетоводител:
F10: 🛡️ Застраховател:
A11: Б. ПРИХОДИ (текуща година) | F11: 🏦 Банка / Ипотека:
B12: Брутен наем (EUR) | C12: =IFERROR(SUM('💶 Плащания наем'!F8:F43),0) -> 600 | F12: 🏛️ Нотариус:
B13: Депозит платен (EUR) | C13: =IFERROR('👤 Наематели'!C18,0) -> 1200 | F13: 📡 Интернет поддръжка:
B14: Депозит върнат (EUR) | C14: =IFERROR('👤 Наематели'!C20,0) -> 600 | F14: 🚒 Аварии (24ч):
A16: В. РАЗХОДИ (текуща година)
B17: Разходи и сметки (EUR) | C17: =IFERROR(SUM('📋 Разходи и сметки'!D7:D66),0) -> 0
B18: Ремонти (EUR) | C18: =IFERROR('🔨 Ремонти'!G4,0) -> 0
B19: ОБЩО РАЗХОДИ (EUR) | C19: =IFERROR(SUM('📋 Разходи и сметки'!D7:D66)+'🔨 Ремонти'!G4,0) -> 0
A21: Г. НЕТЕН ПАРИЧЕН ПОТОК И ДОХОДНОСТ
B22: Нетен паричен поток (EUR) | C22: =IFERROR(C12-C19,0) -> 600
B23: Разходен коефициент (%) | C23: =IFERROR(C19/C12,0) -> 0
B24: Gross Yield (%) | C24: =IFERROR(C12/C5*12,0) -> 0
B25: Net Yield (%) | C25: =IFERROR(C22/C8*12,0) -> 0

Sheet 📂 Документи
A1: 📂 ДОКУМЕНТИ И АРХИВ — Регистър на всички документи
A2: Водете пълна документация — при спор имате доказателства
A3: № | B3: Дата | C3: Вид документ | D3: Издател / Страна | E3: Номер / Референция | F3: Оригинал? | G3: Местоположение на оригинала | H3: Бележки
A4: 1 | C4: Нотариален акт | D4: Нотариус | F4: Да | G4: Личен архив
A5: 2 | C5: Скица от КРНИ | D5: АГКК | F5: Да | G5: Личен архив
A6: 3 | C6: Данъчна оценка | D6: Общинска администрация | F6: Да | G6: Папка 'Данъци'
A7: 4 | C7: Договор за наем — текущ | D7: Наемодател + Наемател | F7: Да | G7: Папка 'Договори'
A8: 5 | C8: Приемо-предавателен протокол | D8: Наемодател + Наемател | F8: Да | G8: Папка 'Договори'
A9: 6 | C9: Застрахователна полица имот | D9: Застраховател | F9: Да | G9: Папка 'Застраховки'
A10: 7 | C10: ЕСС — протокол ОС | D10: Управителен съвет | F10: Да | G10: Папка 'ЕСС'
A11: 8 | C11: Гаранционна карта — котел | D11: Сервиз | F11: Да | G11: Фурнадже шкаф
A12: 9 | C12: Гаранционна карта — климатик | D12: Монтажна фирма | F12: Да | G12: Фурнадже шкаф
A13: 10 | C13: Договор ел. енергия | D13: Доставчик | F13: Не | G13: Скенирано
A14: 11 | C14: Договор интернет | D14: Доставчик | F14: Не | G14: Скенирано
