Workbook

Sheet 📋 Входни данни
A1: 📋 ВХОДНИ ДАННИ — Имоти и параметри за сравнение
A2: Жълти клетки = вашите данни • Сините = автоматично • 1 EUR = 1.95583 лв. (БНБ)
A4: А. ГЛОБАЛНИ ПАРАМЕТРИ — Важи за двата варианта
B5: Брой имоти в портфолиото | C5: 2 | E5: 1–5 (можете да добавите до 5 имота)
B6: Период на анализ (години) | C6: 10 | E6: Колко години напред да изчисляваме
B7: Годишен ръст на наема (%) | C7: 3 | E7: Очакван годишен ръст на наема
B8: Годишен ръст на разходите (%) | C8: 2.5 | E8: Инфлация на разходите
B9: Дисконтов процент (%) | C9: 5 | E9: За NPV изчисление (цена на капитала)
A11: Б. ДАННИ ЗА ИМОТИТЕ — Попълнете за всеки активен имот
B12: Параметър | C12: Имот 1 | E12: Имот 2 | G12: Имот 3 | I12: Имот 4 | K12: Имот 5
B13: ── ПОКУПКА ──
B14: Активен? (Да/Не) | C14: Да | E14: Да | G14: Не | I14: Не | K14: Не
B15: Покупна цена (EUR) | C15: 77000 | E15: 102000 | G15: 0 | I15: 0 | K15: 0
B16: ДДС при покупка (0% или 20%) | C16: 0 | E16: 0 | G16: 0 | I16: 0 | K16: 0
B17: Нотариус + данъци (% от цената) | C17: 3 | E17: 3 | G17: 3 | I17: 3 | K17: 3
B18: Брокерска комисионна (%) | C18: 2 | E18: 2 | G18: 2 | I18: 2 | K18: 2
B19: Ремонт при покупка (EUR) | C19: 7500 | E19: 5000 | G19: 0 | I19: 0 | K19: 0
B20: Обзавеждане при покупка (EUR) | C20: 4000 | E20: 3000 | G20: 0 | I20: 0 | K20: 0
B21: ОБЩА ИНВЕСТИЦИЯ (авт.) | C21: =IFERROR(C14*(1+C15)+C14*C16+C14*C17+C18+C19,0) -> 0 | E21: =IFERROR(E14*(1+E15)+E14*E16+E14*E17+E18+E19,0) -> 0 | G21: =IFERROR(G14*(1+G15)+G14*G16+G14*G17+G18+G19,0) -> 0 | I21: =IFERROR(I14*(1+I15)+I14*I16+I14*I17+I18+I19,0) -> 0 | K21: =IFERROR(K14*(1+K15)+K14*K16+K14*K17+K18+K19,0) -> 0
B22: ── ПРИХОДИ ──
B23: Месечен наем (EUR) | C23: 510 | E23: 612 | G23: 0 | I23: 0 | K23: 0
B24: Вакантност (% от наема) | C24: 8 | E24: 8 | G24: 8 | I24: 8 | K24: 8
B25: Годишен ефективен наем (авт.) | C25: =IFERROR(C23*12*(1-C24),0) -> -42840 | E25: =IFERROR(E23*12*(1-E24),0) -> -51408 | G25: =IFERROR(G23*12*(1-G24),0) -> 0 | I25: =IFERROR(I23*12*(1-I24),0) -> 0 | K25: =IFERROR(K23*12*(1-K24),0) -> 0
B26: ── ГОДИШНИ РАЗХОДИ ──
B27: ЕСС и поддръжка сграда (EUR/год.) | C27: 612 | E27: 736 | G27: 0 | I27: 0 | K27: 0
B28: Застраховка имот (EUR/год.) | C28: 200 | E28: 250 | G28: 0 | I28: 0 | K28: 0
B29: Ремонти и поддръжка (EUR/год.) | C29: 500 | E29: 600 | G29: 0 | I29: 0 | K29: 0
B30: Данък имот и такси (EUR/год.) | C30: 255 | E30: 310 | G30: 0 | I30: 0 | K30: 0
B31: Управление/агенция (% от наема) | C31: 0 | E31: 0 | G31: 0 | I31: 0 | K31: 0
B32: Общо годишни разходи (авт.) | C32: =IFERROR(C27+C28+C29+C30+C24*C31,0) -> 1567 | E32: =IFERROR(E27+E28+E29+E30+E24*E31,0) -> 1896 | G32: =IFERROR(G27+G28+G29+G30+G24*G31,0) -> 0 | I32: =IFERROR(I27+I28+I29+I30+I24*I31,0) -> 0 | K32: =IFERROR(K27+K28+K29+K30+K24*K31,0) -> 0
B33: ── ПРОДАЖБА ──
B34: Планирана продажна цена (EUR) | C34: 120000 | E34: 150000 | G34: 0 | I34: 0 | K34: 0
B35: Брокерска комисионна при продажба (%) | C35: 2 | E35: 2 | G35: 2 | I35: 2 | K35: 2
B36: Планирана година на продажба | C36: 7 | E36: 8 | G36: 0 | I36: 0 | K36: 0
A38: В. СПЕЦИФИЧНИ ПАРАМЕТРИ — ЕООД
B39: Месечно счетоводство (EUR) | C39: 77 | E39: Обикновено 61–153 EUR/мес.
B40: Осигуровки управител (EUR/мес.) | C40: 149 | E40: При мин. осиг. доход ~477 EUR × 31.3%
B41: Годишни такси ТР и банка (EUR) | C41: 51 | E41: Търговски регистър + банкови такси
B42: Ставка КД (%) | C42: 10 | E42: Корпоративен данък — ЗКПО
B43: Ставка данък дивиденти (%) | C43: 5 | E43: ЗДДФЛ чл.38
...

Sheet 👤 Физическо лице
A1: 👤 ФИЗИЧЕСКО ЛИЦЕ — Данъчни изчисления
A2: ДДФЛ 9% ефективна ставка • Нормативни 10% разходи • Нулев данък след 3 год.
A4: 📥 Обща инвестиция | C4: 📈 Годишен нетен доход | E4: 💰 Данъчна тежест/год. | G4: 📊 Net Yield
A6: А. РЕЗУЛТАТИ ПО ИМОТ — Годишен паричен поток
B7: Параметър | C7: Имот 1 | D7: Имот 2 | E7: Имот 3 | F7: Суми
B8: Покупна цена (EUR) | C8: ='📋 Входни данни'!C15 -> 77000 | D8: ='📋 Входни данни'!D15 -> 0 | E8: ='📋 Входни данни'!E15 -> 102000 | F8: =C8+D8+E8 -> 179000
B9: Годишен ефективен наем | C9: ='📋 Входни данни'!C25 -> -42840 | D9: ='📋 Входни данни'!D25 -> 0 | E9: ='📋 Входни данни'!E25 -> -51408 | F9: =C9+D9+E9 -> -94248
B10: – ДДФЛ (9% ефективна) | C10: =-IFERROR('📋 Входни данни'!C25*'📋 Входни данни'!$C$50,0) -> 385560 | D10: =-IFERROR('📋 Входни данни'!D25*'📋 Входни данни'!$C$50,0) -> 0 | E10: =-IFERROR('📋 Входни данни'!E25*'📋 Входни данни'!$C$50,0) -> 462672 | F10: =C10+D10+E10 -> 848232
B11: – Годишни разходи | C11: =-'📋 Входни данни'!C32 -> -1567 | D11: =-'📋 Входни данни'!D32 -> 0 | E11: =-'📋 Входни данни'!E32 -> -1896 | F11: =C11+D11+E11 -> -3463
B12: нетен паричен поток/год. | C12: =IFERROR(C9+C10+C11,0) -> 341153 | D12: =IFERROR(D9+D10+D11,0) -> 0 | E12: =IFERROR(E9+E10+E11,0) -> 409368 | F12: =C12+D12+E12 -> 750521
B13: Обща инвестиция (вкл. ДДС) | C13: ='📋 Входни данни'!C21 -> 0 | D13: ='📋 Входни данни'!D21 -> 0 | E13: ='📋 Входни данни'!E21 -> 0 | F13: =C13+D13+E13 -> 0
B14: Net Yield (%) | C14: =IFERROR(C12/C13,0) -> 0 | D14: =IFERROR(D12/D13,0) -> 0 | E14: =IFERROR(E12/E13,0) -> 0
B15: Gross Yield (%) | C15: =IFERROR(C9/C13,0) -> 0 | D15: =IFERROR(D9/D13,0) -> 0 | E15: =IFERROR(E9/E13,0) -> 0
A17: Б. ДАНЪК ПРИ ПРОДАЖБА — Физическо лице
B18: Параметър | C18: Имот 1 | D18: Имот 2 | E18: Имот 3 | F18: Суми
B19: Продажна цена (EUR) | C19: ='📋 Входни данни'!C34 -> 120000 | D19: ='📋 Входни данни'!D34 -> 0 | E19: ='📋 Входни данни'!E34 -> 150000 | F19: =C19+D19+E19 -> 270000
B20: Покупна цена + разходи | C20: ='📋 Входни данни'!C21 -> 0 | D20: ='📋 Входни данни'!D21 -> 0 | E20: ='📋 Входни данни'!E21 -> 0 | F20: =C20+D20+E20 -> 0
B21: Планирана година на продажба | C21: ='📋 Входни данни'!C36 -> 7 | D21: ='📋 Входни данни'!D36 -> 0 | E21: ='📋 Входни данни'!E36 -> 8 | F21: =C21+D21+E21 -> 15
B22: Данък при продажба след 3 г.
B23: Данък при продажба преди 3 г.
B24: Продажба в год. >3? (Да/Не) | C24: =IF(C21>3,"Да","Не") -> Да | D24: =IF(D21>3,"Да","Не") -> Не | E24: =IF(E21>3,"Да","Не") -> Да
B25: Данък при продажба (EUR) | C25: =IFERROR(IF(C21>3,(C19-C20)*'📋 Входни данни'!$C$51,(C19-C20)*'📋 Входни данни'!$C$52),0) -> 0 | D25: =IFERROR(IF(D21>3,(D19-D20)*'📋 Входни данни'!$C$51,(D19-D20)*'📋 Входни данни'!$C$52),0) -> 0 | E25: =IFERROR(IF(E21>3,(E19-E20)*'📋 Входни данни'!$C$51,(E19-E20)*'📋 Входни данни'!$C$52),0) -> 0 | F25: =C25+D25+E25 -> 0
B26: Нетна печалба от продажба | C26: =IFERROR(C19-C20-C25,0) -> 120000 | D26: =IFERROR(D19-D20-D25,0) -> 0 | E26: =IFERROR(E19-E20-E25,0) -> 150000 | F26: =C26+D26+E26 -> 270000

Sheet 🏢 ЕООД
A1: 🏢 ЕООД — Данъчни изчисления
A2: КД 10% + Дивиденти 5% • Амортизация 2% • Всички реални разходи признати
A5: А. АДМИНИСТРАТИВНИ РАЗХОДИ НА ЕООД — Годишни фиксирани разходи
B6: Параметър | C6: Стойност | D6: Бележка
B7: Счетоводство (EUR/год.) | C7: ='📋 Входни данни'!C39*12 -> 924 | D7: Месечно × 12
B8: Осигуровки управител (EUR/год.) | C8: ='📋 Входни данни'!C40*12 -> 1788 | D8: Месечно × 12
B9: Такси ТР и банка (EUR/год.) | C9: ='📋 Входни данни'!C41 -> 51 | D9: Годишно
B10: ОБЩО АДМИНИСТРАТИВНИ (EUR/год.) | C10: =C7+C8+C9 -> 2763 | D10: Фиксиран overhead на ЕООД
A12: Б. РЕЗУЛТАТИ ПО ИМОТ — Годишен паричен поток при ЕООД
B13: Параметър | C13: Имот 1 | D13: Имот 2 | E13: Имот 3 | F13: Суми
B14: Покупна цена (EUR) | C14: ='📋 Входни данни'!C15 -> 77000 | D14: ='📋 Входни данни'!D15 -> 0 | E14: ='📋 Входни данни'!E15 -> 102000 | F14: =C14+D14+E14 -> 179000
B15: Годишен ефективен наем | C15: ='📋 Входни данни'!C25 -> -42840 | D15: ='📋 Входни данни'!D25 -> 0 | E15: ='📋 Входни данни'!E25 -> -51408 | F15: =C15+D15+E15 -> -94248
B16: – Годишни разходи | C16: =-'📋 Входни данни'!C32 -> -1567 | D16: =-'📋 Входни данни'!D32 -> 0 | E16: =-'📋 Входни данни'!E32 -> -1896 | F16: =C16+D16+E16 -> -3463
B17: – Амортизация имот (2%) | C17: =-IFERROR('📋 Входни данни'!C15*'📋 Входни данни'!$C$44,0) -> -154000 | D17: =-IFERROR('📋 Входни данни'!D15*'📋 Входни данни'!$C$44,0) -> 0 | E17: =-IFERROR('📋 Входни данни'!E15*'📋 Входни данни'!$C$44,0) -> -204000 | F17: =C17+D17+E17 -> -358000
B18: – Амортизация обзавеждане | C18: =-IFERROR('📋 Входни данни'!C20*'📋 Входни данни'!$C$45,0) -> -60000 | D18: =-IFERROR('📋 Входни данни'!D20*'📋 Входни данни'!$C$45,0) -> 0 | E18: =-IFERROR('📋 Входни данни'!E20*'📋 Входни данни'!$C$45,0) -> -45000 | F18: =C18+D18+E18 -> -105000
B19: данъчна печалба | C19: =IFERROR(C15+C16+C17+C18,0) -> -258407 | D19: =IFERROR(D15+D16+D17+D18,0) -> 0 | E19: =IFERROR(E15+E16+E17+E18,0) -> -302304 | F19: =C19+D19+E19 -> -560711
B20: – Корпоративен данък (10%) | C20: =-IFERROR(MAX(C19,0)*'📋 Входни данни'!$C$42,0) -> 0 | D20: =-IFERROR(MAX(D19,0)*'📋 Входни данни'!$C$42,0) -> 0 | E20: =-IFERROR(MAX(E19,0)*'📋 Входни данни'!$C$42,0) -> 0 | F20: =C20+D20+E20 -> 0
B21: нетна печалба | C21: =IFERROR(MAX(C19,0)+C20,0) -> 0 | D21: =IFERROR(MAX(D19,0)+D20,0) -> 0 | E21: =IFERROR(MAX(E19,0)+E20,0) -> 0 | F21: =C21+D21+E21 -> 0
B22: – Данък дивиденти (5%) | C22: =-IFERROR(C21*'📋 Входни данни'!$C$43,0) -> 0 | D22: =-IFERROR(D21*'📋 Входни данни'!$C$43,0) -> 0 | E22: =-IFERROR(E21*'📋 Входни данни'!$C$43,0) -> 0 | F22: =C22+D22+E22 -> 0
B23: в джоба ви (след дивид.) | C23: =IFERROR(C21+C22,0) -> 0 | D23: =IFERROR(D21+D22,0) -> 0 | E23: =IFERROR(E21+E22,0) -> 0 | F23: =C23+D23+E23 -> 0
B24: – Адм. разходи ЕООД (1/N) | C24: =-IFERROR('🏢 ЕООД'!$C$10/MAX('📋 Входни данни'!$C$5,1),0) -> -1381.5 | D24: =-IFERROR('🏢 ЕООД'!$C$10/MAX('📋 Входни данни'!$C$5,1),0) -> -1381.5 | E24: =-IFERROR('🏢 ЕООД'!$C$10/MAX('📋 Входни данни'!$C$5,1),0) -> -1381.5 | F24: =-'🏢 ЕООД'!$C$10 -> -2763
B25: нетен паричен поток/год. | C25: =IFERROR(C23+C24,0) -> -1381.5 | D25: =IFERROR(D23+D24,0) -> -1381.5 | E25: =IFERROR(E23+E24,0) -> -1381.5 | F25: =C25+D25+E25 -> -4144.5
B26: Обща инвестиция | C26: ='📋 Входни данни'!C21 -> 0 | D26: ='📋 Входни данни'!D21 -> 0 | E26: ='📋 Входни данни'!E21 -> 0 | F26: =C26+D26+E26 -> 0
B27: Net Yield (%) | C27: =IFERROR(C25/C26,0) -> 0 | D27: =IFERROR(D25/D26,0) -> 0 | E27: =IFERROR(E25/E26,0) -> 0 | F27: =IFERROR(F25/F26,0) -> 0
B28: Gross Yield (%) | C28: =IFERROR(C15/C26,0) -> 0 | D28: =IFERROR(D15/D26,0) -> 0 | E28: =IFERROR(E15/E26,0) -> 0 | F28: =IFERROR(F25/F26,0) -> 0
A30: В. ДАНЪК ПРИ ПРОДАЖБА — ЕООД (КД 10% върху печалбата)
B31: Параметър | C31: Имот 1 | D31: Имот 2 | E31: Имот 3 | F31: Суми
B32: Продажна цена (EUR) | C32: ='📋 Входни данни'!C34 -> 120000 | D32: ='📋 Входни данни'!D34 -> 0 | E32: ='📋 Входни данни'!E34 -> 150000 | F32: =C32+D32+E32 -> 270000
B33: Покупна цена + разходи | C33: ='📋 Входни данни'!C21 -> 0 | D33: ='📋 Входни данни'!D21 -> 0 | E33: ='📋 Входни данни'!E21 -> 0 | F33: =C33+D33+E33 -> 0
B34: Натрупана амортизация | C34: =IFERROR('📋 Входни данни'!C15*'📋 Входни данни'!$C$44*'📋 Входни данни'!C36,0) -> 1078000 | D34: =IFERROR('📋 Входни данни'!D15*'📋 Входни данни'!$C$44*'📋 Входни данни'!D36,0) -> 0 | E34: =IFERROR('📋 Входни данни'!E15*'📋 Входни данни'!$C$44*'📋 Входни данни'!E36,0) -> 1632000 | F34: =C34+D34+E34 -> 2710000
B35: Счетоводна стойност | C35: =IFERROR(C33-C34,0) -> -1078000 | D35: =IFERROR(D33-D34,0) -> 0 | E35: =IFERROR(E33-E34,0) -> -1632000 | F35: =C35+D35+E35 -> -2710000
B36: Данъчна печалба от продажба | C36: =IFERROR(C32-C35,0) -> 1198000 | D36: =IFERROR(D32-D35,0) -> 0 | E36: =IFERROR(E32-E35,0) -> 1782000 | F36: =C36+D36+E36 -> 2980000
B37: КД 10% при продажба | C37: =IFERROR(MAX(C36,0)*'📋 Входни данни'!$C$42,0) -> 11980000 | D37: =IFERROR(MAX(D36,0)*'📋 Входни данни'!$C$42,0) -> 0 | E37: =IFERROR(MAX(E36,0)*'📋 Входни данни'!$C$42,0) -> 17820000 | F37: =C37+D37+E37 -> 29800000
B38: Нетна печалба след КД | C38: =IFERROR(C36-C37,0) -> -10782000 | D38: =IFERROR(D36-D37,0) -> 0 | E38: =IFERROR(E36-E37,0) -> -16038000 | F38: =C38+D38+E38 -> -26820000
B39: Данък дивиденти 5% | C39: =IFERROR(MAX(C38,0)*'📋 Входни данни'!$C$43,0) -> 0 | D39: =IFERROR(MAX(D38,0)*'📋 Входни данни'!$C$43,0) -> 0 | E39: =IFERROR(MAX(E38,0)*'📋 Входни данни'!$C$43,0) -> 0 | F39: =C39+D39+E39 -> 0
B40: В ДЖОБА ВИ от продажба | C40: =IFERROR(C38-C39,0) -> -10782000 | D40: =IFERROR(D38-D39,0) -> 0 | E40: =IFERROR(E38-E39,0) -> -16038000 | F40: =C40+D40+E40 -> -26820000

Sheet ⚖️ Сравнение
A1: ⚖️ СРАВНЕНИЕ — ФИЗИЧЕСКО ЛИЦЕ vs ЕООД
A2: Автоматична присъда кой вариант е по-изгоден при вашите конкретни данни
B4: =IF('👤 Физическо лице'!F12>'🏢 ЕООД'!F25,"✅ ФИЗИЧЕСКО ЛИЦЕ е по-изгодно при тези данни — по-висок нетен паричен поток.","✅ ЕООД е по-изгодно при тези данни — по-висок нетен паричен поток след всички разходи.") -> ✅ ФИЗИЧЕСКО ЛИЦЕ е по-изгодно при тези данни — по-висок нетен паричен поток.
A6: А. ОСНОВНИ ПОКАЗАТЕЛИ — Пряко сравнение
B7: Показател | C7: 👤 Физическо лице | D7: 🏢 ЕООД | E7: Разлика (ЕООД − ФЛ) | F7: По-добро
B8: Обща инвестиция (EUR) | C8: ='👤 Физическо лице'!F13 -> 0 | D8: ='🏢 ЕООД'!F26 -> 0 | E8: =D8-C8 -> 0 | F8: =IF(D8>C8,"🏢 ЕООД","👤 ФЛ") -> 👤 ФЛ
B9: Годишен нетен паричен поток (EUR) | C9: ='👤 Физическо лице'!F12 -> 750521 | D9: ='🏢 ЕООД'!F25 -> -4144.5 | E9: =D9-C9 -> -754665.5 | F9: =IF(D9>C9,"🏢 ЕООД","👤 ФЛ") -> 👤 ФЛ
B10: Net Yield (%) | C10: =IFERROR('👤 Физическо лице'!F14,0) -> 0 | D10: =IFERROR('🏢 ЕООД'!F27,0) -> 0 | E10: =D10-C10 -> 0 | F10: =IF(D10>C10,"🏢 ЕООД","👤 ФЛ") -> 👤 ФЛ
B11: Gross Yield (%) | C11: =IFERROR('👤 Физическо лице'!F15,0) -> 0 | D11: =IFERROR('🏢 ЕООД'!F28,0) -> 0 | E11: =D11-C11 -> 0 | F11: =IF(D11>C11,"🏢 ЕООД","👤 ФЛ") -> 👤 ФЛ
B12: Годишни данъци — ДДФЛ/КД+Дивиденти | C12: =IFERROR('👤 Физическо лице'!F10,0) -> 848232 | D12: =IFERROR('🏢 ЕООД'!F20+'🏢 ЕООД'!F22,0) -> 0 | E12: =D12-C12 -> -848232 | F12: =IF(D12>C12,"🏢 ЕООД","👤 ФЛ") -> 👤 ФЛ
B13: Административни разходи ЕООД (EUR/год.) | C13: =0 -> 0 | D13: =-'🏢 ЕООД'!$C$10 -> -2763 | E13: =D13-C13 -> -2763 | F13: =IF(ABS(D13)<ABS(C13),"🏢 ЕООД","👤 ФЛ") -> 👤 ФЛ
B14: Данъчна тежест (% от брутния наем) | C14: =IFERROR(ABS('👤 Физическо лице'!F10)/'👤 Физическо лице'!F9,0) -> -9 | D14: =IFERROR(ABS('🏢 ЕООД'!F20+ABS('🏢 ЕООД'!F22))/'🏢 ЕООД'!F15,0) -> 0 | E14: =D14-C14 -> 9 | F14: =IF(D14>C14,"🏢 ЕООД","👤 ФЛ") -> 🏢 ЕООД
A16: Б. СРАВНЕНИЕ ПРИ ПРОДАЖБА
B17: Показател | C17: 👤 Физическо лице | D17: 🏢 ЕООД | E17: Разлика | F17: По-добро
B18: Нетна печалба от продажба (EUR) | C18: ='👤 Физическо лице'!F26 -> 270000 | D18: ='🏢 ЕООД'!F40 -> -26820000 | E18: =D18-C18 -> -27090000 | F18: =IF(D18>C18,"🏢 ЕООД","👤 ФЛ") -> 👤 ФЛ
B19: Данъчна тежест при продажба (EUR) | C19: ='👤 Физическо лице'!F25 -> 0 | D19: ='🏢 ЕООД'!F37+'🏢 ЕООД'!F39 -> 29800000 | E19: =D19-C19 -> 29800000 | F19: =IF(D19>C19,"🏢 ЕООД","👤 ФЛ") -> 🏢 ЕООД
A21: В. КАЧЕСТВЕНО СРАВНЕНИЕ — Не само числа
B22: Фактор | D22: 👤 Физическо лице | F22: 🏢 ЕООД
B23: Административна тежест | C23: ✅ Минимална — 1 декларация/год. | E23: ❌ Месечно счетоводство задължително
B24: Признати разходи | C24: ⚠️ Само 10% нормативни | E24: ✅ 100% реални + амортизация
B25: Данък при продажба (3+ год.) | C25: ✅ Нулев данък при ФЛ | E25: ❌ КД 10% + дивид. 5% при ЕООД
B26: Осигуровки | C26: ✅ Нула при наем | E26: ❌ ~1 791 EUR/год. задължителни
B27: Лична отговорност | C27: ❌ С цялото имущество | E27: ✅ Само до капитала на фирмата
B28: Лихви по ипотека | C28: ❌ Не се признават | E28: ✅ Признат разход при ЕООД
B29: Амортизация на имот | C29: ❌ Невъзможна | E29: ✅ 2%/год. — признат разход
B30: Мащабиране 5+ имота | C30: ⚠️ По-сложно при много имоти | E30: ✅ Структурирано бизнес управление
B31: ДДС (жилищен наем) | C31: ✅ Освободена доставка | E31: ✅ Освободена доставка
B32: Представителност | C32: ⚠️ Лично | E32: ✅ Фирмен облик при банки/партньори
A34: Г. АВТОМАТИЧНИ ИЗВОДИ И ПРЕПОРЪКИ
B35: Годишното предимство (EUR/год.): | C35: =IFERROR('🏢 ЕООД'!F25-'👤 Физическо лице'!F12,0) -> -754665.5 | D35: =IF('🏢 ЕООД'!F25>'👤 Физическо лице'!F12,"🏢 ЕООД генерира повече нетен паричен поток на година.","👤 ФЛ генерира повече нетен паричен поток на година.") -> 👤 ФЛ генерира повече нетен паричен поток на година.
B36: За колко години се покриват разходите за ЕООД: | C36: =IFERROR(IF(('🏢 ЕООД'!F25-'👤 Физическо лице'!F12)>0,'🏢 ЕООД'!$C$10/('🏢 ЕООД'!F25-'👤 Физическо лице'!F12),9999),0) -> 9999 | D36: =IF(C36<5,"⚡ Под 5 г. — ЕООД се изплаща бързо.",IF(C36<9999,"📊 Над 5 г. — направете по-задълбочен анализ.","⚠️ ЕООД не генерира повече от ФЛ при тези данни.")) -> ⚠️ ЕООД не генерира повече от ФЛ при тези данни.
B38: ⚠️ ВАЖНО: Тази калкулация е ориентировъчна. Преди финансово решение консултирайте данъчен специалист. | Числата се базират на данните в лист 'Входни данни'. | При промяна на параметрите — всички изчисления се актуализират автоматично.
